<?xml version="1.0" ?>
<!-- =================================================================================== -->
<!-- |    This document was autogenerated by xacro from talos_full.urdf.xacro          | -->
<!-- |    EDITING THIS FILE BY HAND IS NOT RECOMMENDED                                 | -->
<!-- =================================================================================== -->
<!--

  Copyright (c) 2016, PAL Robotics, S.L.
  All rights reserved.

  This work is licensed under the Creative Commons Attribution-NonCommercial-NoDerivs 3.0 Unported License.
  To view a copy of this license, visit http://creativecommons.org/licenses/by-nc-nd/3.0/ or send a letter to
  Creative Commons, 444 Castro Street, Suite 900, Mountain View, California, 94041, USA.
-->
<robot name="talos_gripper" xmlns:controller="http://playerstage.sourceforge.net/gazebo/xmlschema/#controller" xmlns:interface="http://playerstage.sourceforge.net/gazebo/xmlschema/#interface" xmlns:sensor="http://playerstage.sourceforge.net/gazebo/xmlschema/#sensor" xmlns:xacro="http://ros.org/wiki/xacro">
  <material name="FlatBlack">
    <color rgba="0.1 0.1 0.1 1"/>
  </material>
  
  <link name="base_mount">
    <inertial>
      <mass value="0.0001"/>
      <origin xyz="0 0 0"/>
      <inertia ixx="0.0001" ixy="0.0" ixz="0.0" iyy="0.0001" iyz="0.0" izz="0.0001"/>
    </inertial>
    <visual>
      <origin rpy="0 0 0" xyz="0 0 0"/>
      <geometry>
        <box size="0.001 0.001 0.001"/>
      </geometry>
    </visual>
  </link>
  <joint name="base_mount_joint" type="fixed">
    <origin rpy="3.14159265359 0 0" xyz="0 0 0"/>
    <parent link="base_mount"/>
    <child link="gripper_left_base_link"/>
  </joint>  

  <link name="gripper_left_base_link">
    <inertial>
      <origin rpy="0.00000 0.00000 0.00000" xyz="-0.00534 0.00362 -0.02357"/>
      <mass value="0.61585"/>
      <inertia ixx="0.00047200000" ixy="-0.00000800000" ixz="0.00003500000" iyy="0.00052100000" iyz="0.00000000000" izz="0.00069000000"/>
    </inertial>
    <visual>
      <origin rpy="0 0 0" xyz="0 0 0"/>
      <geometry>
        <mesh filename="package://meshes/gripper/base_link.STL" scale="1 1 1"/>
      </geometry>
      <material name="DarkGrey"/>
    </visual>
    <collision>
      <origin rpy="0 0 0" xyz="0 0 0"/>
      <geometry>
        <mesh filename="package://meshes/gripper/base_link_collision.STL" scale="1 1 1"/>
      </geometry>
    </collision>
  </link>


  <link name="gripper_left_motor_double_link">
    <inertial>
      <origin rpy="0.00000 0.00000 0.00000" xyz="0.02270 0.01781 -0.00977"/>
      <mass value="0.16889"/>
      <inertia ixx="0.001159" ixy="-0.00007000000" ixz="0.00003800000" iyy="0.001221" iyz="-0.00005300000" izz="0.001268"/>
    </inertial>
    <visual>
      <origin rpy="0 0 0" xyz="0 0 0"/>
      <geometry>
        <mesh filename="package://meshes/gripper/gripper_motor_double.STL" scale="1 1 1"/>
      </geometry>
      <material name="Orange"/>
    </visual>
    <collision>
      <origin rpy="0 0 0" xyz="0 0 0"/>
      <geometry>
        <mesh filename="package://meshes/gripper/gripper_motor_double_collision.STL" scale="1 1 1"/>
      </geometry>
    </collision>
  </link>
  <joint name="gripper_left_joint" type="fixed">
    <parent link="gripper_left_base_link"/>
    <child link="gripper_left_motor_double_link"/>
    <origin rpy="0.0 0.0 0.0" xyz="0.0 0.02025 -0.03"/>
    <axis xyz="1 0 0"/>
    <limit effort="1.0" lower="-1.0471975512" upper="0.0" velocity="1.0"/>
    <dynamics damping="1.0" friction="1.0"/>
  </joint>
  <link name="gripper_left_inner_double_link">
    <inertial>
      <origin rpy="0.00000 0.00000 0.00000" xyz="-0.00056 0.03358 -0.01741"/>
      <mass value="0.11922"/>
      <inertia ixx="0.00009100000" ixy="0.00000100000" ixz="-0.00000100000" iyy="0.00015600000" iyz="-0.00003200000" izz="0.00012600000"/>
    </inertial>
    <visual>
      <origin rpy="0 0 0" xyz="0 0 0"/>
      <geometry>
        <mesh filename="package://meshes/gripper/inner_double.STL" scale="1 1 1"/>
      </geometry>
      <material name="Orange"/>
    </visual>
    <collision>
      <origin rpy="0 0 0" xyz="0 0 0"/>
      <geometry>
        <mesh filename="package://meshes/gripper/inner_double_collision.STL" scale="1 1 1"/>
      </geometry>
    </collision>
  </link>
  <joint name="gripper_left_inner_double_joint" type="fixed">
    <parent link="gripper_left_base_link"/>
    <child link="gripper_left_inner_double_link"/>
    <origin rpy="0.0 0.0 0.0" xyz="0.00000 0.00525 -0.05598"/>
    <axis xyz="1 0 0"/>
    <limit effort="100.0" lower="-1.0471975512" upper="0.0" velocity="1.0"/>
    <mimic joint="gripper_left_joint" multiplier="1.0" offset="0.0"/>
  </joint>
  <link name="gripper_left_fingertip_1_link">
    <inertial>
      <origin rpy="0.00000 0.00000 0.00000" xyz="0.00000 0.00460 -0.00254"/>
      <mass value="0.02630"/>
      <inertia ixx="0.00000800000" ixy="0.00000000000" ixz="0.00000000000" iyy="0.00000900000" iyz="0.00000100000" izz="0.00000200000"/>
    </inertial>
    <visual>
      <origin rpy="0 0 0" xyz="0 0 0"/>
      <geometry>
        <mesh filename="package://meshes/gripper/fingertip.STL" scale="1 1 1"/>
      </geometry>
      <material name="DarkGrey"/>
    </visual>
    <collision>
      <origin rpy="0 0 0" xyz="0 0 0"/>
      <geometry>
        <mesh filename="package://meshes/gripper/fingertip_collision.STL" scale="1 1 1"/>
      </geometry>
    </collision>
  </link>
  <joint name="gripper_left_fingertip_1_joint" type="fixed">
    <parent link="gripper_left_inner_double_link"/>
    <child link="gripper_left_fingertip_1_link"/>
    <origin rpy="0.0 0.0 0.0" xyz="0.03200 0.04589 -0.06553"/>
    <axis xyz="1 0 0"/>
    <limit effort="100.0" lower="0.0" upper="1.0471975512" velocity="1.0"/>
    <mimic joint="gripper_left_joint" multiplier="-1.0" offset="0.0"/>
  </joint>
  <link name="gripper_left_fingertip_2_link">
    <inertial>
      <origin rpy="0.00000 0.00000 0.00000" xyz="0.00000 0.00460 -0.00254"/>
      <mass value="0.02630"/>
      <inertia ixx="0.00000800000" ixy="0.00000000000" ixz="0.00000000000" iyy="0.00000900000" iyz="0.00000100000" izz="0.00000200000"/>
    </inertial>
    <visual>
      <origin rpy="0 0 0" xyz="0 0 0"/>
      <geometry>
        <mesh filename="package://meshes/gripper/fingertip.STL" scale="1 1 1"/>
      </geometry>
      <material name="DarkGrey"/>
    </visual>
    <collision>
      <origin rpy="0 0 0" xyz="0 0 0"/>
      <geometry>
        <mesh filename="package://meshes/gripper/fingertip_collision.STL" scale="1 1 1"/>
      </geometry>
    </collision>
  </link>
  <joint name="gripper_left_fingertip_2_joint" type="fixed">
    <parent link="gripper_left_inner_double_link"/>
    <child link="gripper_left_fingertip_2_link"/>
    <origin rpy="0.0 0.0 0.0" xyz="-0.03200 0.04589 -0.06553"/>
    <axis xyz="1 0 0"/>
    <limit effort="100.0" lower="0.0" upper="1.0471975512" velocity="1.0"/>
    <mimic joint="gripper_left_joint" multiplier="-1.0" offset="0.0"/>
  </joint>
  

  <!-- Start of "thumb" finger -->

  <link name="gripper_left_motor_single_link">
    <inertial>
      <origin rpy="0.00000 0.00000 0.00000" xyz="0.02589 -0.01284 -0.00640"/>
      <mass value="0.14765"/>
      <inertia ixx="0.00011500000" ixy="0.00005200000" ixz="0.00002500000" iyy="0.00015300000" iyz="0.00003400000" izz="0.00019000000"/>
    </inertial>
    <visual>
      <origin rpy="0 0 0" xyz="0 0 0"/>
      <geometry>
        <mesh filename="package://meshes/gripper/gripper_motor_single.STL" scale="1 1 1"/>
      </geometry>
      <material name="Orange"/>
    </visual>
    <collision>
      <origin rpy="0 0 0" xyz="0 0 0"/>
      <geometry>
        <mesh filename="package://meshes/gripper/gripper_motor_single_collision.STL" scale="1 1 1"/>
      </geometry>
    </collision>
  </link>
  <joint name="gripper_left_motor_single_joint" type="revolute">
    <parent link="gripper_left_base_link"/>
    <child link="gripper_left_motor_single_link"/>
    <origin rpy="0.0 0.0 0.0" xyz="0.00000 -0.02025 -0.03000"/>
    <axis xyz="1 0 0"/>
    <limit effort="100.0" lower="0.0" upper="1.0471975512" velocity="1.0"/>
    <mimic joint="gripper_left_joint" multiplier="-1.0" offset="0.0"/>
  </joint>
  <link name="gripper_left_inner_single_link">
    <inertial>
      <origin rpy="0.00000 0.00000 0.00000" xyz="0.00000 -0.03253 -0.01883"/>
      <mass value="0.05356"/>
      <inertia ixx="0.00004700000" ixy="-0.00000000000" ixz="-0.00000000000" iyy="0.00003500000" iyz="0.00001700000" izz="0.00002400000"/>
    </inertial>
    <visual>
      <origin rpy="0 0 0" xyz="0 0 0"/>
      <geometry>
        <mesh filename="package://meshes/gripper/inner_single.STL" scale="1 1 1"/>
      </geometry>
      <material name="Orange"/>
    </visual>
    <collision>
      <origin rpy="0 0 0" xyz="0 0 0"/>
      <geometry>
        <mesh filename="package://meshes/gripper/inner_single_collision.STL" scale="1 1 1"/>
      </geometry>
    </collision>
  </link>
  <joint name="gripper_left_inner_single_joint_PASSIVE" type="revolute">
    <parent link="gripper_left_base_link"/>
    <child link="gripper_left_inner_single_link"/>
    <origin rpy="0.0 0.0 0.0" xyz="0.00000 -0.00525 -0.05598"/>
    <axis xyz="1 0 0"/>
    <limit effort="100.0" lower="0.0" upper="1.0471975512" velocity="1.0"/>
    <mimic joint="gripper_left_joint" multiplier="-1.0" offset="0.0"/>
  </joint>
  <link name="gripper_left_fingertip_3_link">
    <inertial>
      <origin rpy="0.00000 0.00000 0.00000" xyz="0.00000 0.00460 -0.00254"/>
      <mass value="0.02630"/>
      <inertia ixx="0.00000800000" ixy="0.00000000000" ixz="0.00000000000" iyy="0.00000900000" iyz="0.00000100000" izz="0.00000200000"/>
    </inertial>
    <visual>
      <origin rpy="0 0 0" xyz="0 0 0"/>
      <geometry>
        <mesh filename="package://meshes/gripper/fingertip.STL" scale="1 1 1"/>
      </geometry>
      <material name="DarkGrey"/>
    </visual>
    <collision>
      <origin rpy="0 0 0" xyz="0 0 0"/>
      <geometry>
        <mesh filename="package://meshes/gripper/fingertip_collision.STL" scale="1 1 1"/>
      </geometry>
    </collision>
  </link>
  <joint name="gripper_left_fingertip_3_joint_PASSIVE" type="revolute">
    <parent link="gripper_left_inner_single_link"/>
    <child link="gripper_left_fingertip_3_link"/>
    <origin rpy="0.0 0.0 3.14159265359" xyz="0.00000 -0.04589 -0.06553"/>
    <axis xyz="1 0 0"/>
    <limit effort="100.0" lower="0.0" upper="1.0471975512" velocity="1.0"/>
    <mimic joint="gripper_left_joint" multiplier="-1.0" offset="0.0"/>
  </joint>
  <gazebo>
    <plugin filename="libroboticsgroup_gazebo_mimic_joint_plugin.so" name="mimic_gripper_left_inner_double_joint">
      <joint>gripper_left_joint</joint>
      <mimicJoint>gripper_left_inner_double_joint</mimicJoint>
      <multiplier>1.0</multiplier>
      <offset>0.0</offset>
      <!-- <hasPID/> -->
    </plugin>
    <plugin filename="libroboticsgroup_gazebo_mimic_joint_plugin.so" name="mimic_gripper_left_fingertip_1_joint">
      <joint>gripper_left_joint</joint>
      <mimicJoint>gripper_left_fingertip_1_joint</mimicJoint>
      <multiplier>-1.0</multiplier>
      <offset>0.0</offset>
      <!-- <hasPID/> -->
    </plugin>
    <plugin filename="libroboticsgroup_gazebo_mimic_joint_plugin.so" name="mimic_gripper_left_fingertip_2_joint">
      <joint>gripper_left_joint</joint>
      <mimicJoint>gripper_left_fingertip_2_joint</mimicJoint>
      <multiplier>-1.0</multiplier>
      <offset>0.0</offset>
      <!-- <hasPID/> -->
    </plugin>
    <plugin filename="libroboticsgroup_gazebo_mimic_joint_plugin.so" name="mimic_gripper_left_inner_single_joint">
      <joint>gripper_left_joint</joint>
      <mimicJoint>gripper_left_inner_single_joint</mimicJoint>
      <multiplier>-1.0</multiplier>
      <offset>0.0</offset>
      <!-- <hasPID/> -->
    </plugin>
    <plugin filename="libroboticsgroup_gazebo_mimic_joint_plugin.so" name="mimic_gripper_left_motor_single_joint">
      <joint>gripper_left_joint</joint>
      <mimicJoint>gripper_left_motor_single_joint</mimicJoint>
      <multiplier>-1.0</multiplier>
      <offset>0.0</offset>
      <!-- <hasPID/> -->
    </plugin>
    <plugin filename="libroboticsgroup_gazebo_mimic_joint_plugin.so" name="mimic_gripper_left_fingertip_3_joint">
      <joint>gripper_left_joint</joint>
      <mimicJoint>gripper_left_fingertip_3_joint</mimicJoint>
      <multiplier>-1.0</multiplier>
      <offset>0.0</offset>
      <!-- <hasPID/> -->
    </plugin>
  </gazebo>
  <!--     <plugin filename="libgazebo_underactuated_finger.so" name="gazebo_${name}_underactuated">
      <actuatedJoint>${name}_joint</actuatedJoint>
      <virtualJoint>
        <name>${name}_inner_double_joint</name>
        <scale_factor>1.0</scale_factor>
      </virtualJoint> -->
  <!--       <virtualJoint>
        <name>${name}_fingertip_1_joint</name>
        <scale_factor>-1.0</scale_factor>
      </virtualJoint>
      <virtualJoint>
        <name>${name}_fingertip_2_joint</name>
        <scale_factor>-1.0</scale_factor>
      </virtualJoint>
      <virtualJoint>
        <name>${name}_motor_single_joint</name>
        <scale_factor>1.0</scale_factor>
      </virtualJoint>
      <virtualJoint>
        <name>${name}_fingertip_3_joint</name>
        <scale_factor>-1.0</scale_factor>
      </virtualJoint> -->
  <!--     </plugin> -->
  <gazebo reference="gripper_left_joint">
    <implicitSpringDamper>1</implicitSpringDamper>
    <provideFeedback>1</provideFeedback>
  </gazebo>
  <gazebo reference="gripper_left_inner_double_joint">
    <implicitSpringDamper>1</implicitSpringDamper>
    <provideFeedback>1</provideFeedback>
  </gazebo>
  <gazebo reference="gripper_left_fingertip_1_joint">
    <implicitSpringDamper>1</implicitSpringDamper>
    <provideFeedback>1</provideFeedback>
  </gazebo>
  <gazebo reference="gripper_left_fingertip_2_joint">
    <implicitSpringDamper>1</implicitSpringDamper>
    <provideFeedback>1</provideFeedback>
  </gazebo>
  <gazebo reference="gripper_left_motor_single_joint">
    <implicitSpringDamper>1</implicitSpringDamper>
    <provideFeedback>1</provideFeedback>
  </gazebo>
  <gazebo reference="gripper_left_fingertip_3_joint">
    <implicitSpringDamper>1</implicitSpringDamper>
    <provideFeedback>1</provideFeedback>
  </gazebo>
  <gazebo reference="gripper_left_base_link">
    <material>Gazebo/FlatBlack</material>
  </gazebo>
  <gazebo reference="gripper_left_motor_double_link">
    <material>Gazebo/Orange</material>
  </gazebo>
  <gazebo reference="gripper_left_inner_double_link">
    <material>Gazebo/Orange</material>
  </gazebo>
  <gazebo reference="gripper_left_fingertip_1_link">
    <material>Gazebo/FlatBlack</material>
  </gazebo>
  <gazebo reference="gripper_left_motor_single_link">
    <material>Gazebo/Orange</material>
  </gazebo>
  <gazebo reference="gripper_left_inner_single_link">
    <material>Gazebo/Orange</material>
  </gazebo>
  <gazebo reference="gripper_left_fingertip_2_link">
    <material>Gazebo/FlatBlack</material>
  </gazebo>
  <gazebo reference="gripper_left_fingertip_3_link">
    <material>Gazebo/FlatBlack</material>
  </gazebo>
  <transmission name="gripper_left_trans">
    <type>transmission_interface/SimpleTransmission</type>
    <actuator name="gripper_left_motor">
      <mechanicalReduction>1.0</mechanicalReduction>
    </actuator>
    <joint name="gripper_left_joint">
      <hardwareInterface>hardware_interface/PositionJointInterface</hardwareInterface>
    </joint>
  </transmission>
  <!-- virtual mimic joints -->
  <!--         <xacro:gripper_virtual_transmission name="${name}_inner_double" reduction="1.0"/>
        <xacro:gripper_virtual_transmission name="${name}_fingertip_1" reduction="1.0"/>
        <xacro:gripper_virtual_transmission name="${name}_fingertip_2" reduction="1.0"/>
        <xacro:gripper_virtual_transmission name="${name}_inner_single" reduction="1.0"/>
        <xacro:gripper_virtual_transmission name="${name}_motor_single" reduction="1.0"/>
        <xacro:gripper_virtual_transmission name="${name}_fingertip_3" reduction="1.0"/> -->
  <!-- define global properties -->
  <!-- <xacro:property name="M_PI" value="3.1415926535897931" /> -->
  <!-- Materials for visualization -->
  <material name="Blue">
    <color rgba="0.0 0.0 0.8 1.0"/>
  </material>
  <material name="Green">
    <color rgba="0.0 0.8 0.0 1.0"/>
  </material>
  <material name="Grey">
    <color rgba="0.7 0.7 0.7 1.0"/>
  </material>
  <material name="LightGrey">
    <color rgba="0.9 0.9 0.9 1.0"/>
  </material>
  <material name="DarkGrey">
    <color rgba="0.2 0.2 0.2 1.0"/>
  </material>
  <material name="Red">
    <color rgba="0.8 0.0 0.0 1.0"/>
  </material>
  <material name="White">
    <color rgba="1.0 1.0 1.0 1.0"/>
  </material>
  <material name="Orange">
    <color rgba="1.0 0.5 0.0 1.0"/>
  </material>

  <!-- Additional links for closed kinematic chain-->
  <link 
    name="gripper_left_motor_single_link_ckc_axis">
    <inertial>
      <origin
        xyz="0 0 0"
        rpy="0 0 0" />
      <mass
        value="0.001" />
      <inertia
        ixx="2.72598612545865E-08"
        ixy="-3.94809105845013E-26"
        ixz="2.92959800279198E-24"
        iyy="2.72598612545865E-08"
        iyz="3.6619975034886E-26"
        izz="2.33655953610741E-08" />
    </inertial>
    <visual>
      <origin
        xyz="0 0 0"
        rpy="0 0 0" />
      <geometry>
        <sphere  radius="0.001"/>
      </geometry>
      <material name="Red">
        <color rgba="1 0 0 1" />
      </material>
    </visual>
  </link>    
  <joint name="gripper_left_inner_single_ckc_joint" type="fixed">
    <parent link="gripper_left_motor_single_link"/>
    <child link="gripper_left_motor_single_link_ckc_axis"/>
    <origin rpy="0.0 0.0 0.0" xyz="0.00000 -0.046 -0.0655"/>
    <axis xyz="0 0 0"/>
    <limit effort="100.0" lower="0.0" upper="1.0471975512" velocity="1.0"/>
  </joint>  
         
  <link
    name="gripper_left_fingertip_3_link_ckc_axis">
    <inertial>
      <origin
        xyz="0 0 0"
        rpy="0 0 0" />
      <mass
        value="0.001" />
      <inertia
        ixx="2.72598612545865E-08"
        ixy="-3.94809105845013E-26"
        ixz="2.92959800279198E-24"
        iyy="2.72598612545865E-08"
        iyz="3.6619975034886E-26"
        izz="2.33655953610741E-08" />
    </inertial>
    <visual>
      <origin
        xyz="0 0 0"
        rpy="0 0 0" />
      <geometry>
        <sphere  radius="0.002"/>
      </geometry>
      <material name="Blue">
        <color rgba="0 0 1 1" />
      </material>
    </visual>
  </link>  
  <joint name="gripper_left_fingertip_3_joint_ckc_axis" type="fixed">
    <parent link="gripper_left_fingertip_3_link"/>
    <child link="gripper_left_fingertip_3_link_ckc_axis"/>
    <origin rpy="0.0 0.0 0" xyz="0 0.015 0.026"/>
    <axis xyz="1 0 0"/>
    <limit effort="100.0" lower="0.0" upper="1.0471975512" velocity="1.0"/>
    <mimic joint="gripper_left_joint" multiplier="-1.0" offset="0.0"/>
  </joint>         

</robot>
