<?xml version="1.0" encoding="utf-8"?>
<!-- =================================================================================== -->
<!-- |    This document was autogenerated by xacro from quadroped.xacro                | -->
<!-- |    EDITING THIS FILE BY HAND IS NOT RECOMMENDED                                 | -->
<!-- =================================================================================== -->
<robot name="quadroped" xmlns:controller="http://playerstage.sourceforge.net/gazebo/xmlschema/#controller" xmlns:interface="http://playerstage.sourceforge.net/gazebo/xmlschema/#interface" xmlns:sensor="http://playerstage.sourceforge.net/gazebo/xmlschema/#sensor" xmlns:xacro="http://playerstage.sourceforge.net/gazebo/xmlschema/#interface">
  <link name="base_link">
    <inertial>
      <origin rpy="0 0 0" xyz="0 0 0"/>
      <mass value="2.0"/>
      <inertia ixx="0.0270833333333" ixy="0" ixz="0" iyy="0.00708333333333" iyz="0" izz="0.0333333333333"/>
    </inertial>
    <visual>
      <origin rpy="0 0 0" xyz="0 0 0"/>
      <geometry>
        <mesh filename="package://quadruped/urdf/cube.obj" scale="0.2 0.4 0.05"/>
        <!-- <box size="${base_w} ${base_l} ${base_h}"/> -->
      </geometry>
      <material name="white">
        <color rgba="1 1 1 1"/>
      </material>
    </visual>
    <collision>
      <origin rpy="0 0 0" xyz="0 0 0"/>
      <geometry>
        <box size="0.2 0.4 0.05"/>
      </geometry>
    </collision>
  </link>
  <!-- <xacro:leg prefix="FL" rx="${0.}" ry="${0.}"/> -->
  <joint name="FL_HFE" type="revolute">
    <parent link="base_link"/>
    <child link="FL_upperleg"/>
    <limit effort="1000" lower="-10" upper="10" velocity="1000"/>
    <axis xyz="1 0 0"/>
    <origin rpy="0 0 0" xyz="-0.1 0.2 0"/>
    <dynamics damping="0.0" friction="0.0"/>
  </joint>
  <link name="FL_upperleg">
    <visual>
      <origin rpy="0 0 0" xyz="0 0 -0.08"/>
      <geometry>
        <!-- <cylinder length="${upper_leg_length}" radius="${upper_leg_radius}"/> -->
        <mesh filename="package://quadruped/urdf/cylinder.obj" scale="0.025 0.025 0.16"/>
      </geometry>
      <material name="grey">
        <color rgba=".4 .4 .4 .1"/>
      </material>
    </visual>
    <collision>
      <origin rpy="0 0 0" xyz="0 0 -0.08"/>
      <geometry>
        <cylinder length="0.16" radius="0.025"/>
      </geometry>
    </collision>
    <inertial>
      <origin rpy="0 0 0" xyz="0 0 -0.0793"/>
      <mass value="0.162"/>
      <inertia ixx="0.000469609" ixy="0.0" ixz="0.0" iyy="0.000469609" iyz="0.0" izz="1e-6"/>
    </inertial>
  </link>
  <joint name="FL_KFE" type="revolute">
    <parent link="FL_upperleg"/>
    <child link="FL_shank"/>
    <limit effort="1000" velocity="10000"/>
    <axis xyz="1 0 0"/>
    <origin rpy="0 0 0" xyz="0 0 -0.16"/>
    <dynamics damping="0.0" friction="0.0"/>
  </joint>
  <link name="FL_shank">
    <contact>
      <lateral_friction value="1.0"/>
      <restitution value="0.5"/>
    </contact>
    <visual>
      <origin rpy="0 0 0" xyz="0 0 -0.08"/>
      <geometry>
        <!-- <cylinder length="${upper_leg_length}" radius="${upper_leg_radius}"/> -->
        <mesh filename="package://quadruped/urdf/cylinder.obj" scale="0.025 0.025 0.16"/>
      </geometry>
      <material name="grey">
        <color rgba=".4 .4 .4 .1"/>
      </material>
    </visual>
    <collision>
      <origin rpy="0 0 0" xyz="0 0 -0.08"/>
      <geometry>
        <cylinder length="0.16" radius="0.025"/>
      </geometry>
    </collision>
    <inertial>
      <origin rpy="0 0 0" xyz="0 0 -0.0756"/>
      <mass value="0.021"/>
      <inertia ixx="0.000087575" ixy="0.0" ixz="0.0" iyy="0.000087575" iyz="0.0" izz="1e-6"/>
    </inertial>
  </link>
  <joint name="FL_END" type="fixed">
    <parent link="FL_shank"/>
    <child link="FL_contact"/>
    <origin rpy="0 0 0" xyz="0 0 -0.16"/>
  </joint>
  <link name="FL_contact">
    <contact>
      <lateral_friction value="1.0"/>
      <restitution value="0.5"/>
    </contact>
    <visual>
      <origin rpy="0 0 0" xyz="0 0 0"/>
      <geometry>
        <!-- <sphere radius="${upper_leg_radius}"/> -->
        <mesh filename="package://quadruped/urdf/sphere.obj" scale="0.025 0.025 0.025"/>
      </geometry>
      <material name="red">
        <color rgba="1. 0. 0. 1."/>
      </material>
    </visual>
    <collision>
      <origin rpy="0 0 0" xyz="0 0 0"/>
      <geometry>
        <sphere radius="0.025"/>
      </geometry>
    </collision>
    <inertial>
      <mass value="0.01"/>
      <inertia ixx="0." ixy="0.0" ixz="0.0" iyy="0." iyz="0.0" izz="0."/>
    </inertial>
  </link>
  <joint name="FR_HFE" type="revolute">
    <parent link="base_link"/>
    <child link="FR_upperleg"/>
    <limit effort="1000" lower="-10" upper="10" velocity="1000"/>
    <axis xyz="1 0 0"/>
    <origin rpy="0 0 0" xyz="0.1 0.2 0"/>
    <dynamics damping="0.0" friction="0.0"/>
  </joint>
  <link name="FR_upperleg">
    <visual>
      <origin rpy="0 0 0" xyz="0 0 -0.08"/>
      <geometry>
        <!-- <cylinder length="${upper_leg_length}" radius="${upper_leg_radius}"/> -->
        <mesh filename="package://quadruped/urdf/cylinder.obj" scale="0.025 0.025 0.16"/>
      </geometry>
      <material name="grey">
        <color rgba=".4 .4 .4 .1"/>
      </material>
    </visual>
    <collision>
      <origin rpy="0 0 0" xyz="0 0 -0.08"/>
      <geometry>
        <cylinder length="0.16" radius="0.025"/>
      </geometry>
    </collision>
    <inertial>
      <origin rpy="0 0 0" xyz="0 0 -0.0793"/>
      <mass value="0.162"/>
      <inertia ixx="0.000469609" ixy="0.0" ixz="0.0" iyy="0.000469609" iyz="0.0" izz="1e-6"/>
    </inertial>
  </link>
  <joint name="FR_KFE" type="revolute">
    <parent link="FR_upperleg"/>
    <child link="FR_shank"/>
    <limit effort="1000" velocity="10000"/>
    <axis xyz="1 0 0"/>
    <origin rpy="0 0 0" xyz="0 0 -0.16"/>
    <dynamics damping="0.0" friction="0.0"/>
  </joint>
  <link name="FR_shank">
    <contact>
      <lateral_friction value="1.0"/>
      <restitution value="0.5"/>
    </contact>
    <visual>
      <origin rpy="0 0 0" xyz="0 0 -0.08"/>
      <geometry>
        <!-- <cylinder length="${upper_leg_length}" radius="${upper_leg_radius}"/> -->
        <mesh filename="package://quadruped/urdf/cylinder.obj" scale="0.025 0.025 0.16"/>
      </geometry>
      <material name="grey">
        <color rgba=".4 .4 .4 .1"/>
      </material>
    </visual>
    <collision>
      <origin rpy="0 0 0" xyz="0 0 -0.08"/>
      <geometry>
        <cylinder length="0.16" radius="0.025"/>
      </geometry>
    </collision>
    <inertial>
      <origin rpy="0 0 0" xyz="0 0 -0.0756"/>
      <mass value="0.021"/>
      <inertia ixx="0.000087575" ixy="0.0" ixz="0.0" iyy="0.000087575" iyz="0.0" izz="1e-6"/>
    </inertial>
  </link>
  <joint name="FR_END" type="fixed">
    <parent link="FR_shank"/>
    <child link="FR_contact"/>
    <origin rpy="0 0 0" xyz="0 0 -0.16"/>
  </joint>
  <link name="FR_contact">
    <contact>
      <lateral_friction value="1.0"/>
      <restitution value="0.5"/>
    </contact>
    <visual>
      <origin rpy="0 0 0" xyz="0 0 0"/>
      <geometry>
        <!-- <sphere radius="${upper_leg_radius}"/> -->
        <mesh filename="package://quadruped/urdf/sphere.obj" scale="0.025 0.025 0.025"/>
      </geometry>
      <material name="red">
        <color rgba="1. 0. 0. 1."/>
      </material>
    </visual>
    <collision>
      <origin rpy="0 0 0" xyz="0 0 0"/>
      <geometry>
        <sphere radius="0.025"/>
      </geometry>
    </collision>
    <inertial>
      <mass value="0.01"/>
      <inertia ixx="0." ixy="0.0" ixz="0.0" iyy="0." iyz="0.0" izz="0."/>
    </inertial>
  </link>
  <joint name="BL_HFE" type="revolute">
    <parent link="base_link"/>
    <child link="BL_upperleg"/>
    <limit effort="1000" lower="-10" upper="10" velocity="1000"/>
    <axis xyz="1 0 0"/>
    <origin rpy="0 0 0" xyz="-0.1 -0.2 0"/>
    <dynamics damping="0.0" friction="0.0"/>
  </joint>
  <link name="BL_upperleg">
    <visual>
      <origin rpy="0 0 0" xyz="0 0 -0.08"/>
      <geometry>
        <!-- <cylinder length="${upper_leg_length}" radius="${upper_leg_radius}"/> -->
        <mesh filename="package://quadruped/urdf/cylinder.obj" scale="0.025 0.025 0.16"/>
      </geometry>
      <material name="grey">
        <color rgba=".4 .4 .4 .1"/>
      </material>
    </visual>
    <collision>
      <origin rpy="0 0 0" xyz="0 0 -0.08"/>
      <geometry>
        <cylinder length="0.16" radius="0.025"/>
      </geometry>
    </collision>
    <inertial>
      <origin rpy="0 0 0" xyz="0 0 -0.0793"/>
      <mass value="0.162"/>
      <inertia ixx="0.000469609" ixy="0.0" ixz="0.0" iyy="0.000469609" iyz="0.0" izz="1e-6"/>
    </inertial>
  </link>
  <joint name="BL_KFE" type="revolute">
    <parent link="BL_upperleg"/>
    <child link="BL_shank"/>
    <limit effort="1000" velocity="10000"/>
    <axis xyz="1 0 0"/>
    <origin rpy="0 0 0" xyz="0 0 -0.16"/>
    <dynamics damping="0.0" friction="0.0"/>
  </joint>
  <link name="BL_shank">
    <contact>
      <lateral_friction value="1.0"/>
      <restitution value="0.5"/>
    </contact>
    <visual>
      <origin rpy="0 0 0" xyz="0 0 -0.08"/>
      <geometry>
        <!-- <cylinder length="${upper_leg_length}" radius="${upper_leg_radius}"/> -->
        <mesh filename="package://quadruped/urdf/cylinder.obj" scale="0.025 0.025 0.16"/>
      </geometry>
      <material name="grey">
        <color rgba=".4 .4 .4 .1"/>
      </material>
    </visual>
    <collision>
      <origin rpy="0 0 0" xyz="0 0 -0.08"/>
      <geometry>
        <cylinder length="0.16" radius="0.025"/>
      </geometry>
    </collision>
    <inertial>
      <origin rpy="0 0 0" xyz="0 0 -0.0756"/>
      <mass value="0.021"/>
      <inertia ixx="0.000087575" ixy="0.0" ixz="0.0" iyy="0.000087575" iyz="0.0" izz="1e-6"/>
    </inertial>
  </link>
  <joint name="BL_END" type="fixed">
    <parent link="BL_shank"/>
    <child link="BL_contact"/>
    <origin rpy="0 0 0" xyz="0 0 -0.16"/>
  </joint>
  <link name="BL_contact">
    <contact>
      <lateral_friction value="1.0"/>
      <restitution value="0.5"/>
    </contact>
    <visual>
      <origin rpy="0 0 0" xyz="0 0 0"/>
      <geometry>
        <!-- <sphere radius="${upper_leg_radius}"/> -->
        <mesh filename="package://quadruped/urdf/sphere.obj" scale="0.025 0.025 0.025"/>
      </geometry>
      <material name="red">
        <color rgba="1. 0. 0. 1."/>
      </material>
    </visual>
    <collision>
      <origin rpy="0 0 0" xyz="0 0 0"/>
      <geometry>
        <sphere radius="0.025"/>
      </geometry>
    </collision>
    <inertial>
      <mass value="0.01"/>
      <inertia ixx="0." ixy="0.0" ixz="0.0" iyy="0." iyz="0.0" izz="0."/>
    </inertial>
  </link>
  <joint name="BR_HFE" type="revolute">
    <parent link="base_link"/>
    <child link="BR_upperleg"/>
    <limit effort="1000" lower="-10" upper="10" velocity="1000"/>
    <axis xyz="1 0 0"/>
    <origin rpy="0 0 0" xyz="0.1 -0.2 0"/>
    <dynamics damping="0.0" friction="0.0"/>
  </joint>
  <link name="BR_upperleg">
    <visual>
      <origin rpy="0 0 0" xyz="0 0 -0.08"/>
      <geometry>
        <!-- <cylinder length="${upper_leg_length}" radius="${upper_leg_radius}"/> -->
        <mesh filename="package://quadruped/urdf/cylinder.obj" scale="0.025 0.025 0.16"/>
      </geometry>
      <material name="grey">
        <color rgba=".4 .4 .4 .1"/>
      </material>
    </visual>
    <collision>
      <origin rpy="0 0 0" xyz="0 0 -0.08"/>
      <geometry>
        <cylinder length="0.16" radius="0.025"/>
      </geometry>
    </collision>
    <inertial>
      <origin rpy="0 0 0" xyz="0 0 -0.0793"/>
      <mass value="0.162"/>
      <inertia ixx="0.000469609" ixy="0.0" ixz="0.0" iyy="0.000469609" iyz="0.0" izz="1e-6"/>
    </inertial>
  </link>
  <joint name="BR_KFE" type="revolute">
    <parent link="BR_upperleg"/>
    <child link="BR_shank"/>
    <limit effort="1000" velocity="10000"/>
    <axis xyz="1 0 0"/>
    <origin rpy="0 0 0" xyz="0 0 -0.16"/>
    <dynamics damping="0.0" friction="0.0"/>
  </joint>
  <link name="BR_shank">
    <contact>
      <lateral_friction value="1.0"/>
      <restitution value="0.5"/>
    </contact>
    <visual>
      <origin rpy="0 0 0" xyz="0 0 -0.08"/>
      <geometry>
        <!-- <cylinder length="${upper_leg_length}" radius="${upper_leg_radius}"/> -->
        <mesh filename="package://quadruped/urdf/cylinder.obj" scale="0.025 0.025 0.16"/>
      </geometry>
      <material name="grey">
        <color rgba=".4 .4 .4 .1"/>
      </material>
    </visual>
    <collision>
      <origin rpy="0 0 0" xyz="0 0 -0.08"/>
      <geometry>
        <cylinder length="0.16" radius="0.025"/>
      </geometry>
    </collision>
    <inertial>
      <origin rpy="0 0 0" xyz="0 0 -0.0756"/>
      <mass value="0.021"/>
      <inertia ixx="0.000087575" ixy="0.0" ixz="0.0" iyy="0.000087575" iyz="0.0" izz="1e-6"/>
    </inertial>
  </link>
  <joint name="BR_END" type="fixed">
    <parent link="BR_shank"/>
    <child link="BR_contact"/>
    <origin rpy="0 0 0" xyz="0 0 -0.16"/>
  </joint>
  <link name="BR_contact">
    <contact>
      <lateral_friction value="1.0"/>
      <restitution value="0.5"/>
    </contact>
    <visual>
      <origin rpy="0 0 0" xyz="0 0 0"/>
      <geometry>
        <!-- <sphere radius="${upper_leg_radius}"/> -->
        <mesh filename="package://quadruped/urdf/sphere.obj" scale="0.025 0.025 0.025"/>
      </geometry>
      <material name="red">
        <color rgba="1. 0. 0. 1."/>
      </material>
    </visual>
    <collision>
      <origin rpy="0 0 0" xyz="0 0 0"/>
      <geometry>
        <sphere radius="0.025"/>
      </geometry>
    </collision>
    <inertial>
      <mass value="0.01"/>
      <inertia ixx="0." ixy="0.0" ixz="0.0" iyy="0." iyz="0.0" izz="0."/>
    </inertial>
  </link>
</robot>

